Workbook
Name SegmentaciónDeDatos_Jugador: #N/A
Name SegmentaciónDeDatos_Jugador: #N/A
Name SegmentaciónDeDatos_Jugador1: ""
Name SegmentaciónDeDatos_POSICION1: #N/A
Name SegmentaciónDeDatos_POSICION1: #N/A
Name SegmentaciónDeDatos_rival: #N/A
Name SegmentaciónDeDatos_rival: #N/A

Sheet PORTADA
B6: INFANTIL A FC BARCELONA
B7: HANDBOL
B11: EQUIP: | D11: Infantil Masculí A
B12: TEMPORADA: | D12: 2025 / 2026
B13: FASE: | D13: 3a Fase · Lliga
B14: COMPETICIÓ: | D14: Lliga Infantil Masculina
B18: NAVEGACIÓ RÀPIDA
B20: 📊 ESTADÍSTICAS INDIVIDUALS
B21: 📊 ESTADÍSTICAS D'EQUIP
B22: 🔍 FILTRE · INDIVIDUAL
B23: 🔍 FILTRE · EQUIP
B24: 📋 DADES
B26: Document generat automàticament · Ús intern FC Barcelona Handbol

Sheet Datos
A1: Jugador | B1: Goles | C1: Paradas | D1: Lanzam. | E1: % lanz | F1: Asistencia | G1: Exclusión | H1: Pase | I1: Área | J1: Pasos | K1: Otro | L1: Recup. | M1: Exclusión + | N1: PenaltiProvocado | O1: JORNADA | P1: FASE | Q1: L/V | R1: rival | S1: POSICION | T1: goles favor | U1: goles contra | V1: lanzamientos realizados | W1: lanzamientos recibidos
A2: Adai | B2: 6 | D2: 7 | E2: =IF(BD_ESTADISTICA_INF_B[[#This Row],[Lanzam.]]="","",IF(BD_ESTADISTICA_INF_B[[#This Row],[POSICION]]="jugador",B2/D2,C2/D2)) -> 0.85714286 | F2: 2 | H2: 1 | L2: 3 | O2: 3 | P2: 3 | Q2: L | R2: H.SANT QUIRZE(L) | S2: =IF(OR(BD_ESTADISTICA_INF_B[[#This Row],[Jugador]]="eudald",BD_ESTADISTICA_INF_B[[#This Row],[Jugador]]="jules",BD_ESTADISTICA_INF_B[[#This Row],[Jugador]]="JAN"),"PORTERO","JUGADOR") -> JUGADOR | T2: =IF(BD_ESTADISTICA_INF_B[[#This Row],[POSICION]]="jugador",BD_ESTADISTICA_INF_B[[#This Row],[Goles]],0) -> 6 | U2: =IF(BD_ESTADISTICA_INF_B[[#This Row],[POSICION]]="portero",BD_ESTADISTICA_INF_B[[#This Row],[Lanzam.]]-BD_ESTADISTICA_INF_B[[#This Row],[Paradas]],0) -> 0 | V2: =IF(BD_ESTADISTICA_INF_B[[#This Row],[POSICION]]="jugador",BD_ESTADISTICA_INF_B[[#This Row],[Lanzam.]],0) -> 7 | W2: =IF(BD_ESTADISTICA_INF_B[[#This Row],[POSICION]]="portero",BD_ESTADISTICA_INF_B[[#This Row],[Lanzam.]],0) -> 0
A3: Albert | B3: 4 | D3: 4 | E3: =IF(BD_ESTADISTICA_INF_B[[#This Row],[Lanzam.]]="","",IF(BD_ESTADISTICA_INF_B[[#This Row],[POSICION]]="jugador",B3/D3,C3/D3)) -> 1 | F3: 2 | L3: 1 | O3: 3 | P3: 3 | Q3: L | R3: H.SANT QUIRZE(L) | S3: =IF(OR(BD_ESTADISTICA_INF_B[[#This Row],[Jugador]]="eudald",BD_ESTADISTICA_INF_B[[#This Row],[Jugador]]="jules",BD_ESTADISTICA_INF_B[[#This Row],[Jugador]]="JAN"),"PORTERO","JUGADOR") -> JUGADOR | T3: =IF(BD_ESTADISTICA_INF_B[[#This Row],[POSICION]]="jugador",BD_ESTADISTICA_INF_B[[#This Row],[Goles]],0) -> 4 | U3: =IF(BD_ESTADISTICA_INF_B[[#This Row],[POSICION]]="portero",BD_ESTADISTICA_INF_B[[#This Row],[Lanzam.]]-BD_ESTADISTICA_INF_B[[#This Row],[Paradas]],0) -> 0 | V3: =IF(BD_ESTADISTICA_INF_B[[#This Row],[POSICION]]="jugador",BD_ESTADISTICA_INF_B[[#This Row],[Lanzam.]],0) -> 4 | W3: =IF(BD_ESTADISTICA_INF_B[[#This Row],[POSICION]]="portero",BD_ESTADISTICA_INF_B[[#This Row],[Lanzam.]],0) -> 0
A4: A. Espeso | B4: 1 | D4: 1 | E4: =IF(BD_ESTADISTICA_INF_B[[#This Row],[Lanzam.]]="","",IF(BD_ESTADISTICA_INF_B[[#This Row],[POSICION]]="jugador",B4/D4,C4/D4)) -> 1 | F4: 4 | O4: 3 | P4: 3 | Q4: L | R4: H.SANT QUIRZE(L) | S4: =IF(OR(BD_ESTADISTICA_INF_B[[#This Row],[Jugador]]="eudald",BD_ESTADISTICA_INF_B[[#This Row],[Jugador]]="jules",BD_ESTADISTICA_INF_B[[#This Row],[Jugador]]="JAN"),"PORTERO","JUGADOR") -> JUGADOR | T4: =IF(BD_ESTADISTICA_INF_B[[#This Row],[POSICION]]="jugador",BD_ESTADISTICA_INF_B[[#This Row],[Goles]],0) -> 1 | U4: =IF(BD_ESTADISTICA_INF_B[[#This Row],[POSICION]]="portero",BD_ESTADISTICA_INF_B[[#This Row],[Lanzam.]]-BD_ESTADISTICA_INF_B[[#This Row],[Paradas]],0) -> 0 | V4: =IF(BD_ESTADISTICA_INF_B[[#This Row],[POSICION]]="jugador",BD_ESTADISTICA_INF_B[[#This Row],[Lanzam.]],0) -> 1 | W4: =IF(BD_ESTADISTICA_INF_B[[#This Row],[POSICION]]="portero",BD_ESTADISTICA_INF_B[[#This Row],[Lanzam.]],0) -> 0
A5: Manel | B5: 6 | D5: 6 | E5: =IF(BD_ESTADISTICA_INF_B[[#This Row],[Lanzam.]]="","",IF(BD_ESTADISTICA_INF_B[[#This Row],[POSICION]]="jugador",B5/D5,C5/D5)) -> 1 | F5: 2 | L5: 1 | O5: 3 | P5: 3 | Q5: L | R5: H.SANT QUIRZE(L) | S5: =IF(OR(BD_ESTADISTICA_INF_B[[#This Row],[Jugador]]="eudald",BD_ESTADISTICA_INF_B[[#This Row],[Jugador]]="jules",BD_ESTADISTICA_INF_B[[#This Row],[Jugador]]="JAN"),"PORTERO","JUGADOR") -> JUGADOR | T5: =IF(BD_ESTADISTICA_INF_B[[#This Row],[POSICION]]="jugador",BD_ESTADISTICA_INF_B[[#This Row],[Goles]],0) -> 6 | U5: =IF(BD_ESTADISTICA_INF_B[[#This Row],[POSICION]]="portero",BD_ESTADISTICA_INF_B[[#This Row],[Lanzam.]]-BD_ESTADISTICA_INF_B[[#This Row],[Paradas]],0) -> 0 | V5: =IF(BD_ESTADISTICA_INF_B[[#This Row],[POSICION]]="jugador",BD_ESTADISTICA_INF_B[[#This Row],[Lanzam.]],0) -> 6 | W5: =IF(BD_ESTADISTICA_INF_B[[#This Row],[POSICION]]="portero",BD_ESTADISTICA_INF_B[[#This Row],[Lanzam.]],0) -> 0
A6: Jordi | E6: =IF(BD_ESTADISTICA_INF_B[[#This Row],[Lanzam.]]="","",IF(BD_ESTADISTICA_INF_B[[#This Row],[POSICION]]="jugador",B6/D6,C6/D6)) | L6: 1 | O6: 3 | P6: 3 | Q6: L | R6: H.SANT QUIRZE(L) | S6: =IF(OR(BD_ESTADISTICA_INF_B[[#This Row],[Jugador]]="eudald",BD_ESTADISTICA_INF_B[[#This Row],[Jugador]]="jules",BD_ESTADISTICA_INF_B[[#This Row],[Jugador]]="JAN"),"PORTERO","JUGADOR") -> JUGADOR | T6: =IF(BD_ESTADISTICA_INF_B[[#This Row],[POSICION]]="jugador",BD_ESTADISTICA_INF_B[[#This Row],[Goles]],0) -> 0 | U6: =IF(BD_ESTADISTICA_INF_B[[#This Row],[POSICION]]="portero",BD_ESTADISTICA_INF_B[[#This Row],[Lanzam.]]-BD_ESTADISTICA_INF_B[[#This Row],[Paradas]],0) -> 0 | V6: =IF(BD_ESTADISTICA_INF_B[[#This Row],[POSICION]]="jugador",BD_ESTADISTICA_INF_B[[#This Row],[Lanzam.]],0) -> 0 | W6: =IF(BD_ESTADISTICA_INF_B[[#This Row],[POSICION]]="portero",BD_ESTADISTICA_INF_B[[#This Row],[Lanzam.]],0) -> 0
A7: Roger | B7: 7 | D7: 8 | E7: =IF(BD_ESTADISTICA_INF_B[[#This Row],[Lanzam.]]="","",IF(BD_ESTADISTICA_INF_B[[#This Row],[POSICION]]="jugador",B7/D7,C7/D7)) -> 0.875 | N7: 1 | O7: 3 | P7: 3 | Q7: L | R7: H.SANT QUIRZE(L) | S7: =IF(OR(BD_ESTADISTICA_INF_B[[#This Row],[Jugador]]="eudald",BD_ESTADISTICA_INF_B[[#This Row],[Jugador]]="jules",BD_ESTADISTICA_INF_B[[#This Row],[Jugador]]="JAN"),"PORTERO","JUGADOR") -> JUGADOR | T7: =IF(BD_ESTADISTICA_INF_B[[#This Row],[POSICION]]="jugador",BD_ESTADISTICA_INF_B[[#This Row],[Goles]],0) -> 7 | U7: =IF(BD_ESTADISTICA_INF_B[[#This Row],[POSICION]]="portero",BD_ESTADISTICA_INF_B[[#This Row],[Lanzam.]]-BD_ESTADISTICA_INF_B[[#This Row],[Paradas]],0) -> 0 | V7: =IF(BD_ESTADISTICA_INF_B[[#This Row],[POSICION]]="jugador",BD_ESTADISTICA_INF_B[[#This Row],[Lanzam.]],0) -> 8 | W7: =IF(BD_ESTADISTICA_INF_B[[#This Row],[POSICION]]="portero",BD_ESTADISTICA_INF_B[[#This Row],[Lanzam.]],0) -> 0
A8: Martí | B8: 2 | D8: 2 | E8: =IF(BD_ESTADISTICA_INF_B[[#This Row],[Lanzam.]]="","",IF(BD_ESTADISTICA_INF_B[[#This Row],[POSICION]]="jugador",B8/D8,C8/D8)) -> 1 | F8: 6 | J8: 1 | O8: 3 | P8: 3 | Q8: L | R8: H.SANT QUIRZE(L) | S8: =IF(OR(BD_ESTADISTICA_INF_B[[#This Row],[Jugador]]="eudald",BD_ESTADISTICA_INF_B[[#This Row],[Jugador]]="jules",BD_ESTADISTICA_INF_B[[#This Row],[Jugador]]="JAN"),"PORTERO","JUGADOR") -> JUGADOR | T8: =IF(BD_ESTADISTICA_INF_B[[#This Row],[POSICION]]="jugador",BD_ESTADISTICA_INF_B[[#This Row],[Goles]],0) -> 2 | U8: =IF(BD_ESTADISTICA_INF_B[[#This Row],[POSICION]]="portero",BD_ESTADISTICA_INF_B[[#This Row],[Lanzam.]]-BD_ESTADISTICA_INF_B[[#This Row],[Paradas]],0) -> 0 | V8: =IF(BD_ESTADISTICA_INF_B[[#This Row],[POSICION]]="jugador",BD_ESTADISTICA_INF_B[[#This Row],[Lanzam.]],0) -> 2 | W8: =IF(BD_ESTADISTICA_INF_B[[#This Row],[POSICION]]="portero",BD_ESTADISTICA_INF_B[[#This Row],[Lanzam.]],0) -> 0
A9: Biel | B9: 2 | D9: 3 | E9: =IF(BD_ESTADISTICA_INF_B[[#This Row],[Lanzam.]]="","",IF(BD_ESTADISTICA_INF_B[[#This Row],[POSICION]]="jugador",B9/D9,C9/D9)) -> 0.66666667 | L9: 2 | O9: 3 | P9: 3 | Q9: L | R9: H.SANT QUIRZE(L) | S9: =IF(OR(BD_ESTADISTICA_INF_B[[#This Row],[Jugador]]="eudald",BD_ESTADISTICA_INF_B[[#This Row],[Jugador]]="jules",BD_ESTADISTICA_INF_B[[#This Row],[Jugador]]="JAN"),"PORTERO","JUGADOR") -> JUGADOR | T9: =IF(BD_ESTADISTICA_INF_B[[#This Row],[POSICION]]="jugador",BD_ESTADISTICA_INF_B[[#This Row],[Goles]],0) -> 2 | U9: =IF(BD_ESTADISTICA_INF_B[[#This Row],[POSICION]]="portero",BD_ESTADISTICA_INF_B[[#This Row],[Lanzam.]]-BD_ESTADISTICA_INF_B[[#This Row],[Paradas]],0) -> 0 | V9: =IF(BD_ESTADISTICA_INF_B[[#This Row],[POSICION]]="jugador",BD_ESTADISTICA_INF_B[[#This Row],[Lanzam.]],0) -> 3 | W9: =IF(BD_ESTADISTICA_INF_B[[#This Row],[POSICION]]="portero",BD_ESTADISTICA_INF_B[[#This Row],[Lanzam.]],0) -> 0
A10: Joan Pau | B10: 3 | D10: 5 | E10: =IF(BD_ESTADISTICA_INF_B[[#This Row],[Lanzam.]]="","",IF(BD_ESTADISTICA_INF_B[[#This Row],[POSICION]]="jugador",B10/D10,C10/D10)) -> 0.6 | F10: 5 | L10: 3 | O10: 3 | P10: 3 | Q10: L | R10: H.SANT QUIRZE(L) | S10: =IF(OR(BD_ESTADISTICA_INF_B[[#This Row],[Jugador]]="eudald",BD_ESTADISTICA_INF_B[[#This Row],[Jugador]]="jules",BD_ESTADISTICA_INF_B[[#This Row],[Jugador]]="JAN"),"PORTERO","JUGADOR") -> JUGADOR | T10: =IF(BD_ESTADISTICA_INF_B[[#This Row],[POSICION]]="jugador",BD_ESTADISTICA_INF_B[[#This Row],[Goles]],0) -> 3 | U10: =IF(BD_ESTADISTICA_INF_B[[#This Row],[POSICION]]="portero",BD_ESTADISTICA_INF_B[[#This Row],[Lanzam.]]-BD_ESTADISTICA_INF_B[[#This Row],[Paradas]],0) -> 0 | V10: =IF(BD_ESTADISTICA_INF_B[[#This Row],[POSICION]]="jugador",BD_ESTADISTICA_INF_B[[#This Row],[Lanzam.]],0) -> 5 | W10: =IF(BD_ESTADISTICA_INF_B[[#This Row],[POSICION]]="portero",BD_ESTADISTICA_INF_B[[#This Row],[Lanzam.]],0) -> 0
A11: Gerard | B11: 4 | D11: 5 | E11: =IF(BD_ESTADISTICA_INF_B[[#This Row],[Lanzam.]]="","",IF(BD_ESTADISTICA_INF_B[[#This Row],[POSICION]]="jugador",B11/D11,C11/D11)) -> 0.8 | F11: 1 | H11: 1 | L11: 1 | O11: 3 | P11: 3 | Q11: L | R11: H.SANT QUIRZE(L) | S11: =IF(OR(BD_ESTADISTICA_INF_B[[#This Row],[Jugador]]="eudald",BD_ESTADISTICA_INF_B[[#This Row],[Jugador]]="jules",BD_ESTADISTICA_INF_B[[#This Row],[Jugador]]="JAN"),"PORTERO","JUGADOR") -> JUGADOR | T11: =IF(BD_ESTADISTICA_INF_B[[#This Row],[POSICION]]="jugador",BD_ESTADISTICA_INF_B[[#This Row],[Goles]],0) -> 4 | U11: =IF(BD_ESTADISTICA_INF_B[[#This Row],[POSICION]]="portero",BD_ESTADISTICA_INF_B[[#This Row],[Lanzam.]]-BD_ESTADISTICA_INF_B[[#This Row],[Paradas]],0) -> 0 | V11: =IF(BD_ESTADISTICA_INF_B[[#This Row],[POSICION]]="jugador",BD_ESTADISTICA_INF_B[[#This Row],[Lanzam.]],0) -> 5 | W11: =IF(BD_ESTADISTICA_INF_B[[#This Row],[POSICION]]="portero",BD_ESTADISTICA_INF_B[[#This Row],[Lanzam.]],0) -> 0
A12: Marçal | E12: =IF(BD_ESTADISTICA_INF_B[[#This Row],[Lanzam.]]="","",IF(BD_ESTADISTICA_INF_B[[#This Row],[POSICION]]="jugador",B12/D12,C12/D12)) | O12: 3 | P12: 3 | Q12: L | R12: H.SANT QUIRZE(L) | S12: =IF(OR(BD_ESTADISTICA_INF_B[[#This Row],[Jugador]]="eudald",BD_ESTADISTICA_INF_B[[#This Row],[Jugador]]="jules",BD_ESTADISTICA_INF_B[[#This Row],[Jugador]]="JAN"),"PORTERO","JUGADOR") -> JUGADOR | T12: =IF(BD_ESTADISTICA_INF_B[[#This Row],[POSICION]]="jugador",BD_ESTADISTICA_INF_B[[#This Row],[Goles]],0) -> 0 | U12: =IF(BD_ESTADISTICA_INF_B[[#This Row],[POSICION]]="portero",BD_ESTADISTICA_INF_B[[#This Row],[Lanzam.]]-BD_ESTADISTICA_INF_B[[#This Row],[Paradas]],0) -> 0 | V12: =IF(BD_ESTADISTICA_INF_B[[#This Row],[POSICION]]="jugador",BD_ESTADISTICA_INF_B[[#This Row],[Lanzam.]],0) -> 0 | W12: =IF(BD_ESTADISTICA_INF_B[[#This Row],[POSICION]]="portero",BD_ESTADISTICA_INF_B[[#This Row],[Lanzam.]],0) -> 0
A13: Unai | B13: 5 | D13: 5 | E13: =IF(BD_ESTADISTICA_INF_B[[#This Row],[Lanzam.]]="","",IF(BD_ESTADISTICA_INF_B[[#This Row],[POSICION]]="jugador",B13/D13,C13/D13)) -> 1 | F13: 2 | L13: 6 | O13: 3 | P13: 3 | Q13: L | R13: H.SANT QUIRZE(L) | S13: =IF(OR(BD_ESTADISTICA_INF_B[[#This Row],[Jugador]]="eudald",BD_ESTADISTICA_INF_B[[#This Row],[Jugador]]="jules",BD_ESTADISTICA_INF_B[[#This Row],[Jugador]]="JAN"),"PORTERO","JUGADOR") -> JUGADOR | T13: =IF(BD_ESTADISTICA_INF_B[[#This Row],[POSICION]]="jugador",BD_ESTADISTICA_INF_B[[#This Row],[Goles]],0) -> 5 | U13: =IF(BD_ESTADISTICA_INF_B[[#This Row],[POSICION]]="portero",BD_ESTADISTICA_INF_B[[#This Row],[Lanzam.]]-BD_ESTADISTICA_INF_B[[#This Row],[Paradas]],0) -> 0 | V13: =IF(BD_ESTADISTICA_INF_B[[#This Row],[POSICION]]="jugador",BD_ESTADISTICA_INF_B[[#This Row],[Lanzam.]],0) -> 5 | W13: =IF(BD_ESTADISTICA_INF_B[[#This Row],[POSICION]]="portero",BD_ESTADISTICA_INF_B[[#This Row],[Lanzam.]],0) -> 0
A14: Leo | E14: =IF(BD_ESTADISTICA_INF_B[[#This Row],[Lanzam.]]="","",IF(BD_ESTADISTICA_INF_B[[#This Row],[POSICION]]="jugador",B14/D14,C14/D14)) | O14: 3 | P14: 3 | Q14: L | R14: H.SANT QUIRZE(L) | S14: =IF(OR(BD_ESTADISTICA_INF_B[[#This Row],[Jugador]]="eudald",BD_ESTADISTICA_INF_B[[#This Row],[Jugador]]="jules",BD_ESTADISTICA_INF_B[[#This Row],[Jugador]]="JAN"),"PORTERO","JUGADOR") -> JUGADOR | T14: =IF(BD_ESTADISTICA_INF_B[[#This Row],[POSICION]]="jugador",BD_ESTADISTICA_INF_B[[#This Row],[Goles]],0) -> 0 | U14: =IF(BD_ESTADISTICA_INF_B[[#This Row],[POSICION]]="portero",BD_ESTADISTICA_INF_B[[#This Row],[Lanzam.]]-BD_ESTADISTICA_INF_B[[#This Row],[Paradas]],0) -> 0 | V14: =IF(BD_ESTADISTICA_INF_B[[#This Row],[POSICION]]="jugador",BD_ESTADISTICA_INF_B[[#This Row],[Lanzam.]],0) -> 0 | W14: =IF(BD_ESTADISTICA_INF_B[[#This Row],[POSICION]]="portero",BD_ESTADISTICA_INF_B[[#This Row],[Lanzam.]],0) -> 0
A15: A. Estapé | B15: 3 | D15: 3 | E15: =IF(BD_ESTADISTICA_INF_B[[#This Row],[Lanzam.]]="","",IF(BD_ESTADISTICA_INF_B[[#This Row],[POSICION]]="jugador",B15/D15,C15/D15)) -> 1 | F15: 3 | L15: 1 | O15: 3 | P15: 3 | Q15: L | R15: H.SANT QUIRZE(L) | S15: =IF(OR(BD_ESTADISTICA_INF_B[[#This Row],[Jugador]]="eudald",BD_ESTADISTICA_INF_B[[#This Row],[Jugador]]="jules",BD_ESTADISTICA_INF_B[[#This Row],[Jugador]]="JAN"),"PORTERO","JUGADOR") -> JUGADOR | T15: =IF(BD_ESTADISTICA_INF_B[[#This Row],[POSICION]]="jugador",BD_ESTADISTICA_INF_B[[#This Row],[Goles]],0) -> 3 | U15: =IF(BD_ESTADISTICA_INF_B[[#This Row],[POSICION]]="portero",BD_ESTADISTICA_INF_B[[#This Row],[Lanzam.]]-BD_ESTADISTICA_INF_B[[#This Row],[Paradas]],0) -> 0 | V15: =IF(BD_ESTADISTICA_INF_B[[#This Row],[POSICION]]="jugador",BD_ESTADISTICA_INF_B[[#This Row],[Lanzam.]],0) -> 3 | W15: =IF(BD_ESTADISTICA_INF_B[[#This Row],[POSICION]]="portero",BD_ESTADISTICA_INF_B[[#This Row],[Lanzam.]],0) -> 0
A16: Jan | B16: 1 | C16: 1 | D16: 4 | E16: =IF(BD_ESTADISTICA_INF_B[[#This Row],[Lanzam.]]="","",IF(BD_ESTADISTICA_INF_B[[#This Row],[POSICION]]="jugador",B16/D16,C16/D16)) -> 0.25 | O16: 3 | P16: 3 | Q16: L | R16: H.SANT QUIRZE(L) | S16: =IF(OR(BD_ESTADISTICA_INF_B[[#This Row],[Jugador]]="eudald",BD_ESTADISTICA_INF_B[[#This Row],[Jugador]]="jules",BD_ESTADISTICA_INF_B[[#This Row],[Jugador]]="JAN"),"PORTERO","JUGADOR") -> PORTERO | T16: =IF(BD_ESTADISTICA_INF_B[[#This Row],[POSICION]]="jugador",BD_ESTADISTICA_INF_B[[#This Row],[Goles]],0) -> 0 | U16: =IF(BD_ESTADISTICA_INF_B[[#This Row],[POSICION]]="portero",BD_ESTADISTICA_INF_B[[#This Row],[Lanzam.]]-BD_ESTADISTICA_INF_B[[#This Row],[Paradas]],0) -> 3 | V16: =IF(BD_ESTADISTICA_INF_B[[#This Row],[POSICION]]="jugador",BD_ESTADISTICA_INF_B[[#This Row],[Lanzam.]],0) -> 0 | W16: =IF(BD_ESTADISTICA_INF_B[[#This Row],[POSICION]]="portero",BD_ESTADISTICA_INF_B[[#This Row],[Lanzam.]],0) -> 4
A17: Jules | E17: =IF(BD_ESTADISTICA_INF_B[[#This Row],[Lanzam.]]="","",IF(BD_ESTADISTICA_INF_B[[#This Row],[POSICION]]="jugador",B17/D17,C17/D17)) | O17: 3 | P17: 3 | Q17: L | R17: H.SANT QUIRZE(L) | S17: =IF(OR(BD_ESTADISTICA_INF_B[[#This Row],[Jugador]]="eudald",BD_ESTADISTICA_INF_B[[#This Row],[Jugador]]="jules",BD_ESTADISTICA_INF_B[[#This Row],[Jugador]]="JAN"),"PORTERO","JUGADOR") -> PORTERO | T17: =IF(BD_ESTADISTICA_INF_B[[#This Row],[POSICION]]="jugador",BD_ESTADISTICA_INF_B[[#This Row],[Goles]],0) -> 0 | U17: =IF(BD_ESTADISTICA_INF_B[[#This Row],[POSICION]]="portero",BD_ESTADISTICA_INF_B[[#This Row],[Lanzam.]]-BD_ESTADISTICA_INF_B[[#This Row],[Paradas]],0) -> 0 | V17: =IF(BD_ESTADISTICA_INF_B[[#This Row],[POSICION]]="jugador",BD_ESTADISTICA_INF_B[[#This Row],[Lanzam.]],0) -> 0 | W17: =IF(BD_ESTADISTICA_INF_B[[#This Row],[POSICION]]="portero",BD_ESTADISTICA_INF_B[[#This Row],[Lanzam.]],0) -> 0
A18: Eudald | B18: 5 | C18: 5 | D18: 10 | E18: =IF(BD_ESTADISTICA_INF_B[[#This Row],[Lanzam.]]="","",IF(BD_ESTADISTICA_INF_B[[#This Row],[POSICION]]="jugador",B18/D18,C18/D18)) -> 0.5 | F18: 1 | O18: 3 | P18: 3 | Q18: L | R18: H.SANT QUIRZE(L) | S18: =IF(OR(BD_ESTADISTICA_INF_B[[#This Row],[Jugador]]="eudald",BD_ESTADISTICA_INF_B[[#This Row],[Jugador]]="jules",BD_ESTADISTICA_INF_B[[#This Row],[Jugador]]="JAN"),"PORTERO","JUGADOR") -> PORTERO | T18: =IF(BD_ESTADISTICA_INF_B[[#This Row],[POSICION]]="jugador",BD_ESTADISTICA_INF_B[[#This Row],[Goles]],0) -> 0 | U18: =IF(BD_ESTADISTICA_INF_B[[#This Row],[POSICION]]="portero",BD_ESTADISTICA_INF_B[[#This Row],[Lanzam.]]-BD_ESTADISTICA_INF_B[[#This Row],[Paradas]],0) -> 5 | V18: =IF(BD_ESTADISTICA_INF_B[[#This Row],[POSICION]]="jugador",BD_ESTADISTICA_INF_B[[#This Row],[Lanzam.]],0) -> 0 | W18: =IF(BD_ESTADISTICA_INF_B[[#This Row],[POSICION]]="portero",BD_ESTADISTICA_INF_B[[#This Row],[Lanzam.]],0) -> 10
A19: David | B19: 5 | D19: 5 | E19: =IF(BD_ESTADISTICA_INF_B[[#This Row],[Lanzam.]]="","",IF(BD_ESTADISTICA_INF_B[[#This Row],[POSICION]]="jugador",B19/D19,C19/D19)) -> 1 | G19: 1 | J19: 1 | O19: 3 | P19: 3 | Q19: L | R19: H.SANT QUIRZE(L) | S19: =IF(OR(BD_ESTADISTICA_INF_B[[#This Row],[Jugador]]="eudald",BD_ESTADISTICA_INF_B[[#This Row],[Jugador]]="jules",BD_ESTADISTICA_INF_B[[#This Row],[Jugador]]="JAN"),"PORTERO","JUGADOR") -> JUGADOR | T19: =IF(BD_ESTADISTICA_INF_B[[#This Row],[POSICION]]="jugador",BD_ESTADISTICA_INF_B[[#This Row],[Goles]],0) -> 5 | U19: =IF(BD_ESTADISTICA_INF_B[[#This Row],[POSICION]]="portero",BD_ESTADISTICA_INF_B[[#This Row],[Lanzam.]]-BD_ESTADISTICA_INF_B[[#This Row],[Paradas]],0) -> 0 | V19: =IF(BD_ESTADISTICA_INF_B[[#This Row],[POSICION]]="jugador",BD_ESTADISTICA_INF_B[[#This Row],[Lanzam.]],0) -> 5 | W19: =IF(BD_ESTADISTICA_INF_B[[#This Row],[POSICION]]="portero",BD_ESTADISTICA_INF_B[[#This Row],[Lanzam.]],0) -> 0
A20: Maxim | E20: =IF(BD_ESTADISTICA_INF_B[[#This Row],[Lanzam.]]="","",IF(BD_ESTADISTICA_INF_B[[#This Row],[POSICION]]="jugador",B20/D20,C20/D20)) | O20: 3 | P20: 3 | Q20: L | R20: H.SANT QUIRZE(L) | S20: =IF(OR(BD_ESTADISTICA_INF_B[[#This Row],[Jugador]]="eudald",BD_ESTADISTICA_INF_B[[#This Row],[Jugador]]="jules",BD_ESTADISTICA_INF_B[[#This Row],[Jugador]]="JAN"),"PORTERO","JUGADOR") -> JUGADOR | T20: =IF(BD_ESTADISTICA_INF_B[[#This Row],[POSICION]]="jugador",BD_ESTADISTICA_INF_B[[#This Row],[Goles]],0) -> 0 | U20: =IF(BD_ESTADISTICA_INF_B[[#This Row],[POSICION]]="portero",BD_ESTADISTICA_INF_B[[#This Row],[Lanzam.]]-BD_ESTADISTICA_INF_B[[#This Row],[Paradas]],0) -> 0 | V20: =IF(BD_ESTADISTICA_INF_B[[#This Row],[POSICION]]="jugador",BD_ESTADISTICA_INF_B[[#This Row],[Lanzam.]],0) -> 0 | W20: =IF(BD_ESTADISTICA_INF_B[[#This Row],[POSICION]]="portero",BD_ESTADISTICA_INF_B[[#This Row],[Lanzam.]],0) -> 0
A21: Adai | B21: 9 | D21: 9 | E21: =IF(BD_ESTADISTICA_INF_B[[#This Row],[Lanzam.]]="","",IF(BD_ESTADISTICA_INF_B[[#This Row],[POSICION]]="jugador",B21/D21,C21/D21)) -> 1 | F21: 2 | G21: 1 | L21: 3 | M21: 1 | O21: 4 | P21: 3 | Q21: V | R21: VIROLAI (V) | S21: =IF(OR(BD_ESTADISTICA_INF_B[[#This Row],[Jugador]]="eudald",BD_ESTADISTICA_INF_B[[#This Row],[Jugador]]="jules",BD_ESTADISTICA_INF_B[[#This Row],[Jugador]]="JAN"),"PORTERO","JUGADOR") -> JUGADOR | T21: =IF(BD_ESTADISTICA_INF_B[[#This Row],[POSICION]]="jugador",BD_ESTADISTICA_INF_B[[#This Row],[Goles]],0) -> 9 | U21: =IF(BD_ESTADISTICA_INF_B[[#This Row],[POSICION]]="portero",BD_ESTADISTICA_INF_B[[#This Row],[Lanzam.]]-BD_ESTADISTICA_INF_B[[#This Row],[Paradas]],0) -> 0 | V21: =IF(BD_ESTADISTICA_INF_B[[#This Row],[POSICION]]="jugador",BD_ESTADISTICA_INF_B[[#This Row],[Lanzam.]],0) -> 9 | W21: =IF(BD_ESTADISTICA_INF_B[[#This Row],[POSICION]]="portero",BD_ESTADISTICA_INF_B[[#This Row],[Lanzam.]],0) -> 0
A22: Albert | B22: 5 | D22: 5 | E22: =IF(BD_ESTADISTICA_INF_B[[#This Row],[Lanzam.]]="","",IF(BD_ESTADISTICA_INF_B[[#This Row],[POSICION]]="jugador",B22/D22,C22/D22)) -> 1 | G22: 1 | L22: 1 | O22: 4 | P22: 3 | Q22: V | R22: VIROLAI (V) | S22: =IF(OR(BD_ESTADISTICA_INF_B[[#This Row],[Jugador]]="eudald",BD_ESTADISTICA_INF_B[[#This Row],[Jugador]]="jules",BD_ESTADISTICA_INF_B[[#This Row],[Jugador]]="JAN"),"PORTERO","JUGADOR") -> JUGADOR | T22: =IF(BD_ESTADISTICA_INF_B[[#This Row],[POSICION]]="jugador",BD_ESTADISTICA_INF_B[[#This Row],[Goles]],0) -> 5 | U22: =IF(BD_ESTADISTICA_INF_B[[#This Row],[POSICION]]="portero",BD_ESTADISTICA_INF_B[[#This Row],[Lanzam.]]-BD_ESTADISTICA_INF_B[[#This Row],[Paradas]],0) -> 0 | V22: =IF(BD_ESTADISTICA_INF_B[[#This Row],[POSICION]]="jugador",BD_ESTADISTICA_INF_B[[#This Row],[Lanzam.]],0) -> 5 | W22: =IF(BD_ESTADISTICA_INF_B[[#This Row],[POSICION]]="portero",BD_ESTADISTICA_INF_B[[#This Row],[Lanzam.]],0) -> 0
A23: A. Espeso | E23: =IF(BD_ESTADISTICA_INF_B[[#This Row],[Lanzam.]]="","",IF(BD_ESTADISTICA_INF_B[[#This Row],[POSICION]]="jugador",B23/D23,C23/D23)) | F23: 6 | H23: 1 | N23: 1 | O23: 4 | P23: 3 | Q23: V | R23: VIROLAI (V) | S23: =IF(OR(BD_ESTADISTICA_INF_B[[#This Row],[Jugador]]="eudald",BD_ESTADISTICA_INF_B[[#This Row],[Jugador]]="jules",BD_ESTADISTICA_INF_B[[#This Row],[Jugador]]="JAN"),"PORTERO","JUGADOR") -> JUGADOR | T23: =IF(BD_ESTADISTICA_INF_B[[#This Row],[POSICION]]="jugador",BD_ESTADISTICA_INF_B[[#This Row],[Goles]],0) -> 0 | U23: =IF(BD_ESTADISTICA_INF_B[[#This Row],[POSICION]]="portero",BD_ESTADISTICA_INF_B[[#This Row],[Lanzam.]]-BD_ESTADISTICA_INF_B[[#This Row],[Paradas]],0) -> 0 | V23: =IF(BD_ESTADISTICA_INF_B[[#This Row],[POSICION]]="jugador",BD_ESTADISTICA_INF_B[[#This Row],[Lanzam.]],0) -> 0 | W23: =IF(BD_ESTADISTICA_INF_B[[#This Row],[POSICION]]="portero",BD_ESTADISTICA_INF_B[[#This Row],[Lanzam.]],0) -> 0
A24: Manel | E24: =IF(BD_ESTADISTICA_INF_B[[#This Row],[Lanzam.]]="","",IF(BD_ESTADISTICA_INF_B[[#This Row],[POSICION]]="jugador",B24/D24,C24/D24)) | O24: 4 | P24: 3 | Q24: V | R24: VIROLAI (V) | S24: =IF(OR(BD_ESTADISTICA_INF_B[[#This Row],[Jugador]]="eudald",BD_ESTADISTICA_INF_B[[#This Row],[Jugador]]="jules",BD_ESTADISTICA_INF_B[[#This Row],[Jugador]]="JAN"),"PORTERO","JUGADOR") -> JUGADOR | T24: =IF(BD_ESTADISTICA_INF_B[[#This Row],[POSICION]]="jugador",BD_ESTADISTICA_INF_B[[#This Row],[Goles]],0) -> 0 | U24: =IF(BD_ESTADISTICA_INF_B[[#This Row],[POSICION]]="portero",BD_ESTADISTICA_INF_B[[#This Row],[Lanzam.]]-BD_ESTADISTICA_INF_B[[#This Row],[Paradas]],0) -> 0 | V24: =IF(BD_ESTADISTICA_INF_B[[#This Row],[POSICION]]="jugador",BD_ESTADISTICA_INF_B[[#This Row],[Lanzam.]],0) -> 0 | W24: =IF(BD_ESTADISTICA_INF_B[[#This Row],[POSICION]]="portero",BD_ESTADISTICA_INF_B[[#This Row],[Lanzam.]],0) -> 0
A25: Jordi | B25: 2 | D25: 2 | E25: =IF(BD_ESTADISTICA_INF_B[[#This Row],[Lanzam.]]="","",IF(BD_ESTADISTICA_INF_B[[#This Row],[POSICION]]="jugador",B25/D25,C25/D25)) -> 1 | F25: 3 | G25: 1 | H25: 1 | O25: 4 | P25: 3 | Q25: V | R25: VIROLAI (V) | S25: =IF(OR(BD_ESTADISTICA_INF_B[[#This Row],[Jugador]]="eudald",BD_ESTADISTICA_INF_B[[#This Row],[Jugador]]="jules",BD_ESTADISTICA_INF_B[[#This Row],[Jugador]]="JAN"),"PORTERO","JUGADOR") -> JUGADOR | T25: =IF(BD_ESTADISTICA_INF_B[[#This Row],[POSICION]]="jugador",BD_ESTADISTICA_INF_B[[#This Row],[Goles]],0) -> 2 | U25: =IF(BD_ESTADISTICA_INF_B[[#This Row],[POSICION]]="portero",BD_ESTADISTICA_INF_B[[#This Row],[Lanzam.]]-BD_ESTADISTICA_INF_B[[#This Row],[Paradas]],0) -> 0 | V25: =IF(BD_ESTADISTICA_INF_B[[#This Row],[POSICION]]="jugador",BD_ESTADISTICA_INF_B[[#This Row],[Lanzam.]],0) -> 2 | W25: =IF(BD_ESTADISTICA_INF_B[[#This Row],[POSICION]]="portero",BD_ESTADISTICA_INF_B[[#This Row],[Lanzam.]],0) -> 0
A26: Roger | B26: 4 | D26: 5 | E26: =IF(BD_ESTADISTICA_INF_B[[#This Row],[Lanzam.]]="","",IF(BD_ESTADISTICA_INF_B[[#This Row],[POSICION]]="jugador",B26/D26,C26/D26)) -> 0.8 | F26: 1 | L26: 3 | O26: 4 | P26: 3 | Q26: V | R26: VIROLAI (V) | S26: =IF(OR(BD_ESTADISTICA_INF_B[[#This Row],[Jugador]]="eudald",BD_ESTADISTICA_INF_B[[#This Row],[Jugador]]="jules",BD_ESTADISTICA_INF_B[[#This Row],[Jugador]]="JAN"),"PORTERO","JUGADOR") -> JUGADOR | T26: =IF(BD_ESTADISTICA_INF_B[[#This Row],[POSICION]]="jugador",BD_ESTADISTICA_INF_B[[#This Row],[Goles]],0) -> 4 | U26: =IF(BD_ESTADISTICA_INF_B[[#This Row],[POSICION]]="portero",BD_ESTADISTICA_INF_B[[#This Row],[Lanzam.]]-BD_ESTADISTICA_INF_B[[#This Row],[Paradas]],0) -> 0 | V26: =IF(BD_ESTADISTICA_INF_B[[#This Row],[POSICION]]="jugador",BD_ESTADISTICA_INF_B[[#This Row],[Lanzam.]],0) -> 5 | W26: =IF(BD_ESTADISTICA_INF_B[[#This Row],[POSICION]]="portero",BD_ESTADISTICA_INF_B[[#This Row],[Lanzam.]],0) -> 0
A27: Martí | B27: 3 | D27: 3 | E27: =IF(BD_ESTADISTICA_INF_B[[#This Row],[Lanzam.]]="","",IF(BD_ESTADISTICA_INF_B[[#This Row],[POSICION]]="jugador",B27/D27,C27/D27)) -> 1 | F27: 3 | G27: 1 | O27: 4 | P27: 3 | Q27: V | R27: VIROLAI (V) | S27: =IF(OR(BD_ESTADISTICA_INF_B[[#This Row],[Jugador]]="eudald",BD_ESTADISTICA_INF_B[[#This Row],[Jugador]]="jules",BD_ESTADISTICA_INF_B[[#This Row],[Jugador]]="JAN"),"PORTERO","JUGADOR") -> JUGADOR | T27: =IF(BD_ESTADISTICA_INF_B[[#This Row],[POSICION]]="jugador",BD_ESTADISTICA_INF_B[[#This Row],[Goles]],0) -> 3 | U27: =IF(BD_ESTADISTICA_INF_B[[#This Row],[POSICION]]="portero",BD_ESTADISTICA_INF_B[[#This Row],[Lanzam.]]-BD_ESTADISTICA_INF_B[[#This Row],[Paradas]],0) -> 0 | V27: =IF(BD_ESTADISTICA_INF_B[[#This Row],[POSICION]]="jugador",BD_ESTADISTICA_INF_B[[#This Row],[Lanzam.]],0) -> 3 | W27: =IF(BD_ESTADISTICA_INF_B[[#This Row],[POSICION]]="portero",BD_ESTADISTICA_INF_B[[#This Row],[Lanzam.]],0) -> 0
A28: Biel | B28: 5 | D28: 6 | E28: =IF(BD_ESTADISTICA_INF_B[[#This Row],[Lanzam.]]="","",IF(BD_ESTADISTICA_INF_B[[#This Row],[POSICION]]="jugador",B28/D28,C28/D28)) -> 0.83333333 | L28: 3 | O28: 4 | P28: 3 | Q28: V | R28: VIROLAI (V) | S28: =IF(OR(BD_ESTADISTICA_INF_B[[#This Row],[Jugador]]="eudald",BD_ESTADISTICA_INF_B[[#This Row],[Jugador]]="jules",BD_ESTADISTICA_INF_B[[#This Row],[Jugador]]="JAN"),"PORTERO","JUGADOR") -> JUGADOR | T28: =IF(BD_ESTADISTICA_INF_B[[#This Row],[POSICION]]="jugador",BD_ESTADISTICA_INF_B[[#This Row],[Goles]],0) -> 5 | U28: =IF(BD_ESTADISTICA_INF_B[[#This Row],[POSICION]]="portero",BD_ESTADISTICA_INF_B[[#This Row],[Lanzam.]]-BD_ESTADISTICA_INF_B[[#This Row],[Paradas]],0) -> 0 | V28: =IF(BD_ESTADISTICA_INF_B[[#This Row],[POSICION]]="jugador",BD_ESTADISTICA_INF_B[[#This Row],[Lanzam.]],0) -> 6 | W28: =IF(BD_ESTADISTICA_INF_B[[#This Row],[POSICION]]="portero",BD_ESTADISTICA_INF_B[[#This Row],[Lanzam.]],0) -> 0
A29: Joan Pau | B29: 5 | D29: 5 | E29: =IF(BD_ESTADISTICA_INF_B[[#This Row],[Lanzam.]]="","",IF(BD_ESTADISTICA_INF_B[[#This Row],[POSICION]]="jugador",B29/D29,C29/D29)) -> 1 | F29: 1 | L29: 1 | O29: 4 | P29: 3 | Q29: V | R29: VIROLAI (V) | S29: =IF(OR(BD_ESTADISTICA_INF_B[[#This Row],[Jugador]]="eudald",BD_ESTADISTICA_INF_B[[#This Row],[Jugador]]="jules",BD_ESTADISTICA_INF_B[[#This Row],[Jugador]]="JAN"),"PORTERO","JUGADOR") -> JUGADOR | T29: =IF(BD_ESTADISTICA_INF_B[[#This Row],[POSICION]]="jugador",BD_ESTADISTICA_INF_B[[#This Row],[Goles]],0) -> 5 | U29: =IF(BD_ESTADISTICA_INF_B[[#This Row],[POSICION]]="portero",BD_ESTADISTICA_INF_B[[#This Row],[Lanzam.]]-BD_ESTADISTICA_INF_B[[#This Row],[Paradas]],0) -> 0 | V29: =IF(BD_ESTADISTICA_INF_B[[#This Row],[POSICION]]="jugador",BD_ESTADISTICA_INF_B[[#This Row],[Lanzam.]],0) -> 5 | W29: =IF(BD_ESTADISTICA_INF_B[[#This Row],[POSICION]]="portero",BD_ESTADISTICA_INF_B[[#This Row],[Lanzam.]],0) -> 0
A30: Gerard | E30: =IF(BD_ESTADISTICA_INF_B[[#This Row],[Lanzam.]]="","",IF(BD_ESTADISTICA_INF_B[[#This Row],[POSICION]]="jugador",B30/D30,C30/D30)) | G30: 1 | O30: 4 | P30: 3 | Q30: V | R30: VIROLAI (V) | S30: =IF(OR(BD_ESTADISTICA_INF_B[[#This Row],[Jugador]]="eudald",BD_ESTADISTICA_INF_B[[#This Row],[Jugador]]="jules",BD_ESTADISTICA_INF_B[[#This Row],[Jugador]]="JAN"),"PORTERO","JUGADOR") -> JUGADOR | T30: =IF(BD_ESTADISTICA_INF_B[[#This Row],[POSICION]]="jugador",BD_ESTADISTICA_INF_B[[#This Row],[Goles]],0) -> 0 | U30: =IF(BD_ESTADISTICA_INF_B[[#This Row],[POSICION]]="portero",BD_ESTADISTICA_INF_B[[#This Row],[Lanzam.]]-BD_ESTADISTICA_INF_B[[#This Row],[Paradas]],0) -> 0 | V30: =IF(BD_ESTADISTICA_INF_B[[#This Row],[POSICION]]="jugador",BD_ESTADISTICA_INF_B[[#This Row],[Lanzam.]],0) -> 0 | W30: =IF(BD_ESTADISTICA_INF_B[[#This Row],[POSICION]]="portero",BD_ESTADISTICA_INF_B[[#This Row],[Lanzam.]],0) -> 0
A31: Marçal | B31: 2 | D31: 3 | E31: =IF(BD_ESTADISTICA_INF_B[[#This Row],[Lanzam.]]="","",IF(BD_ESTADISTICA_INF_B[[#This Row],[POSICION]]="jugador",B31/D31,C31/D31)) -> 0.66666667 | F31: 4 | H31: 3 | L31: 2 | O31: 4 | P31: 3 | Q31: V | R31: VIROLAI (V) | S31: =IF(OR(BD_ESTADISTICA_INF_B[[#This Row],[Jugador]]="eudald",BD_ESTADISTICA_INF_B[[#This Row],[Jugador]]="jules",BD_ESTADISTICA_INF_B[[#This Row],[Jugador]]="JAN"),"PORTERO","JUGADOR") -> JUGADOR | T31: =IF(BD_ESTADISTICA_INF_B[[#This Row],[POSICION]]="jugador",BD_ESTADISTICA_INF_B[[#This Row],[Goles]],0) -> 2 | U31: =IF(BD_ESTADISTICA_INF_B[[#This Row],[POSICION]]="portero",BD_ESTADISTICA_INF_B[[#This Row],[Lanzam.]]-BD_ESTADISTICA_INF_B[[#This Row],[Paradas]],0) -> 0 | V31: =IF(BD_ESTADISTICA_INF_B[[#This Row],[POSICION]]="jugador",BD_ESTADISTICA_INF_B[[#This Row],[Lanzam.]],0) -> 3 | W31: =IF(BD_ESTADISTICA_INF_B[[#This Row],[POSICION]]="portero",BD_ESTADISTICA_INF_B[[#This Row],[Lanzam.]],0) -> 0
A32: Unai | E32: =IF(BD_ESTADISTICA_INF_B[[#This Row],[Lanzam.]]="","",IF(BD_ESTADISTICA_INF_B[[#This Row],[POSICION]]="jugador",B32/D32,C32/D32)) | O32: 4 | P32: 3 | Q32: V | R32: VIROLAI (V) | S32: =IF(OR(BD_ESTADISTICA_INF_B[[#This Row],[Jugador]]="eudald",BD_ESTADISTICA_INF_B[[#This Row],[Jugador]]="jules",BD_ESTADISTICA_INF_B[[#This Row],[Jugador]]="JAN"),"PORTERO","JUGADOR") -> JUGADOR | T32: =IF(BD_ESTADISTICA_INF_B[[#This Row],[POSICION]]="jugador",BD_ESTADISTICA_INF_B[[#This Row],[Goles]],0) -> 0 | U32: =IF(BD_ESTADISTICA_INF_B[[#This Row],[POSICION]]="portero",BD_ESTADISTICA_INF_B[[#This Row],[Lanzam.]]-BD_ESTADISTICA_INF_B[[#This Row],[Paradas]],0) -> 0 | V32: =IF(BD_ESTADISTICA_INF_B[[#This Row],[POSICION]]="jugador",BD_ESTADISTICA_INF_B[[#This Row],[Lanzam.]],0) -> 0 | W32: =IF(BD_ESTADISTICA_INF_B[[#This Row],[POSICION]]="portero",BD_ESTADISTICA_INF_B[[#This Row],[Lanzam.]],0) -> 0
A33: Leo | B33: 11 | D33: 12 | E33: =IF(BD_ESTADISTICA_INF_B[[#This Row],[Lanzam.]]="","",IF(BD_ESTADISTICA_INF_B[[#This Row],[POSICION]]="jugador",B33/D33,C33/D33)) -> 0.91666667 | F33: 1 | L33: 6 | M33: 1 | N33: 1 | O33: 4 | P33: 3 | Q33: V | R33: VIROLAI (V) | S33: =IF(OR(BD_ESTADISTICA_INF_B[[#This Row],[Jugador]]="eudald",BD_ESTADISTICA_INF_B[[#This Row],[Jugador]]="jules",BD_ESTADISTICA_INF_B[[#This Row],[Jugador]]="JAN"),"PORTERO","JUGADOR") -> JUGADOR | T33: =IF(BD_ESTADISTICA_INF_B[[#This Row],[POSICION]]="jugador",BD_ESTADISTICA_INF_B[[#This Row],[Goles]],0) -> 11 | U33: =IF(BD_ESTADISTICA_INF_B[[#This Row],[POSICION]]="portero",BD_ESTADISTICA_INF_B[[#This Row],[Lanzam.]]-BD_ESTADISTICA_INF_B[[#This Row],[Paradas]],0) -> 0 | V33: =IF(BD_ESTADISTICA_INF_B[[#This Row],[POSICION]]="jugador",BD_ESTADISTICA_INF_B[[#This Row],[Lanzam.]],0) -> 12 | W33: =IF(BD_ESTADISTICA_INF_B[[#This Row],[POSICION]]="portero",BD_ESTADISTICA_INF_B[[#This Row],[Lanzam.]],0) -> 0
A34: A. Estapé | B34: 1 | D34: 2 | E34: =IF(BD_ESTADISTICA_INF_B[[#This Row],[Lanzam.]]="","",IF(BD_ESTADISTICA_INF_B[[#This Row],[POSICION]]="jugador",B34/D34,C34/D34)) -> 0.5 | F34: 4 | L34: 2 | O34: 4 | P34: 3 | Q34: V | R34: VIROLAI (V) | S34: =IF(OR(BD_ESTADISTICA_INF_B[[#This Row],[Jugador]]="eudald",BD_ESTADISTICA_INF_B[[#This Row],[Jugador]]="jules",BD_ESTADISTICA_INF_B[[#This Row],[Jugador]]="JAN"),"PORTERO","JUGADOR") -> JUGADOR | T34: =IF(BD_ESTADISTICA_INF_B[[#This Row],[POSICION]]="jugador",BD_ESTADISTICA_INF_B[[#This Row],[Goles]],0) -> 1 | U34: =IF(BD_ESTADISTICA_INF_B[[#This Row],[POSICION]]="portero",BD_ESTADISTICA_INF_B[[#This Row],[Lanzam.]]-BD_ESTADISTICA_INF_B[[#This Row],[Paradas]],0) -> 0 | V34: =IF(BD_ESTADISTICA_INF_B[[#This Row],[POSICION]]="jugador",BD_ESTADISTICA_INF_B[[#This Row],[Lanzam.]],0) -> 2 | W34: =IF(BD_ESTADISTICA_INF_B[[#This Row],[POSICION]]="portero",BD_ESTADISTICA_INF_B[[#This Row],[Lanzam.]],0) -> 0
A35: Jan | E35: =IF(BD_ESTADISTICA_INF_B[[#This Row],[Lanzam.]]="","",IF(BD_ESTADISTICA_INF_B[[#This Row],[POSICION]]="jugador",B35/D35,C35/D35)) | O35: 4 | P35: 3 | Q35: V | R35: VIROLAI (V) | S35: =IF(OR(BD_ESTADISTICA_INF_B[[#This Row],[Jugador]]="eudald",BD_ESTADISTICA_INF_B[[#This Row],[Jugador]]="jules",BD_ESTADISTICA_INF_B[[#This Row],[Jugador]]="JAN"),"PORTERO","JUGADOR") -> PORTERO | T35: =IF(BD_ESTADISTICA_INF_B[[#This Row],[POSICION]]="jugador",BD_ESTADISTICA_INF_B[[#This Row],[Goles]],0) -> 0 | U35: =IF(BD_ESTADISTICA_INF_B[[#This Row],[POSICION]]="portero",BD_ESTADISTICA_INF_B[[#This Row],[Lanzam.]]-BD_ESTADISTICA_INF_B[[#This Row],[Paradas]],0) -> 0 | V35: =IF(BD_ESTADISTICA_INF_B[[#This Row],[POSICION]]="jugador",BD_ESTADISTICA_INF_B[[#This Row],[Lanzam.]],0) -> 0 | W35: =IF(BD_ESTADISTICA_INF_B[[#This Row],[POSICION]]="portero",BD_ESTADISTICA_INF_B[[#This Row],[Lanzam.]],0) -> 0
A36: Jules | B36: 6 | C36: 6 | D36: 14 | E36: =IF(BD_ESTADISTICA_INF_B[[#This Row],[Lanzam.]]="","",IF(BD_ESTADISTICA_INF_B[[#This Row],[POSICION]]="jugador",B36/D36,C36/D36)) -> 0.42857143 | O36: 4 | P36: 3 | Q36: V | R36: VIROLAI (V) | S36: =IF(OR(BD_ESTADISTICA_INF_B[[#This Row],[Jugador]]="eudald",BD_ESTADISTICA_INF_B[[#This Row],[Jugador]]="jules",BD_ESTADISTICA_INF_B[[#This Row],[Jugador]]="JAN"),"PORTERO","JUGADOR") -> PORTERO | T36: =IF(BD_ESTADISTICA_INF_B[[#This Row],[POSICION]]="jugador",BD_ESTADISTICA_INF_B[[#This Row],[Goles]],0) -> 0 | U36: =IF(BD_ESTADISTICA_INF_B[[#This Row],[POSICION]]="portero",BD_ESTADISTICA_INF_B[[#This Row],[Lanzam.]]-BD_ESTADISTICA_INF_B[[#This Row],[Paradas]],0) -> 8 | V36: =IF(BD_ESTADISTICA_INF_B[[#This Row],[POSICION]]="jugador",BD_ESTADISTICA_INF_B[[#This Row],[Lanzam.]],0) -> 0 | W36: =IF(BD_ESTADISTICA_INF_B[[#This Row],[POSICION]]="portero",BD_ESTADISTICA_INF_B[[#This Row],[Lanzam.]],0) -> 14
A37: Eudald | B37: 5 | C37: 5 | D37: 11 | E37: =IF(BD_ESTADISTICA_INF_B[[#This Row],[Lanzam.]]="","",IF(BD_ESTADISTICA_INF_B[[#This Row],[POSICION]]="jugador",B37/D37,C37/D37)) -> 0.45454545 | O37: 4 | P37: 3 | Q37: V | R37: VIROLAI (V) | S37: =IF(OR(BD_ESTADISTICA_INF_B[[#This Row],[Jugador]]="eudald",BD_ESTADISTICA_INF_B[[#This Row],[Jugador]]="jules",BD_ESTADISTICA_INF_B[[#This Row],[Jugador]]="JAN"),"PORTERO","JUGADOR") -> PORTERO | T37: =IF(BD_ESTADISTICA_INF_B[[#This Row],[POSICION]]="jugador",BD_ESTADISTICA_INF_B[[#This Row],[Goles]],0) -> 0 | U37: =IF(BD_ESTADISTICA_INF_B[[#This Row],[POSICION]]="portero",BD_ESTADISTICA_INF_B[[#This Row],[Lanzam.]]-BD_ESTADISTICA_INF_B[[#This Row],[Paradas]],0) -> 6 | V37: =IF(BD_ESTADISTICA_INF_B[[#This Row],[POSICION]]="jugador",BD_ESTADISTICA_INF_B[[#This Row],[Lanzam.]],0) -> 0 | W37: =IF(BD_ESTADISTICA_INF_B[[#This Row],[POSICION]]="portero",BD_ESTADISTICA_INF_B[[#This Row],[Lanzam.]],0) -> 11
A38: David | B38: 2 | D38: 3 | E38: =IF(BD_ESTADISTICA_INF_B[[#This Row],[Lanzam.]]="","",IF(BD_ESTADISTICA_INF_B[[#This Row],[POSICION]]="jugador",B38/D38,C38/D38)) -> 0.66666667 | L38: 2 | O38: 4 | P38: 3 | Q38: V | R38: VIROLAI (V) | S38: =IF(OR(BD_ESTADISTICA_INF_B[[#This Row],[Jugador]]="eudald",BD_ESTADISTICA_INF_B[[#This Row],[Jugador]]="jules",BD_ESTADISTICA_INF_B[[#This Row],[Jugador]]="JAN"),"PORTERO","JUGADOR") -> JUGADOR | T38: =IF(BD_ESTADISTICA_INF_B[[#This Row],[POSICION]]="jugador",BD_ESTADISTICA_INF_B[[#This Row],[Goles]],0) -> 2 | U38: =IF(BD_ESTADISTICA_INF_B[[#This Row],[POSICION]]="portero",BD_ESTADISTICA_INF_B[[#This Row],[Lanzam.]]-BD_ESTADISTICA_INF_B[[#This Row],[Paradas]],0) -> 0 | V38: =IF(BD_ESTADISTICA_INF_B[[#This Row],[POSICION]]="jugador",BD_ESTADISTICA_INF_B[[#This Row],[Lanzam.]],0) -> 3 | W38: =IF(BD_ESTADISTICA_INF_B[[#This Row],[POSICION]]="portero",BD_ESTADISTICA_INF_B[[#This Row],[Lanzam.]],0) -> 0
A39: Maxim | E39: =IF(BD_ESTADISTICA_INF_B[[#This Row],[Lanzam.]]="","",IF(BD_ESTADISTICA_INF_B[[#This Row],[POSICION]]="jugador",B39/D39,C39/D39)) | O39: 4 | P39: 3 | Q39: V | R39: VIROLAI (V) | S39: =IF(OR(BD_ESTADISTICA_INF_B[[#This Row],[Jugador]]="eudald",BD_ESTADISTICA_INF_B[[#This Row],[Jugador]]="jules",BD_ESTADISTICA_INF_B[[#This Row],[Jugador]]="JAN"),"PORTERO","JUGADOR") -> JUGADOR | T39: =IF(BD_ESTADISTICA_INF_B[[#This Row],[POSICION]]="jugador",BD_ESTADISTICA_INF_B[[#This Row],[Goles]],0) -> 0 | U39: =IF(BD_ESTADISTICA_INF_B[[#This Row],[POSICION]]="portero",BD_ESTADISTICA_INF_B[[#This Row],[Lanzam.]]-BD_ESTADISTICA_INF_B[[#This Row],[Paradas]],0) -> 0 | V39: =IF(BD_ESTADISTICA_INF_B[[#This Row],[POSICION]]="jugador",BD_ESTADISTICA_INF_B[[#This Row],[Lanzam.]],0) -> 0 | W39: =IF(BD_ESTADISTICA_INF_B[[#This Row],[POSICION]]="portero",BD_ESTADISTICA_INF_B[[#This Row],[Lanzam.]],0) -> 0
A40: Adai | B40: 1 | D40: 2 | E40: =IF(BD_ESTADISTICA_INF_B[[#This Row],[Lanzam.]]="","",IF(BD_ESTADISTICA_INF_B[[#This Row],[POSICION]]="jugador",B40/D40,C40/D40)) -> 0.5 | F40: 1 | H40: 2 | N40: 1 | O40: 1 | P40: 3 | Q40: L | R40: CH PALAUTORDERA (L) | S40: =IF(OR(BD_ESTADISTICA_INF_B[[#This Row],[Jugador]]="eudald",BD_ESTADISTICA_INF_B[[#This Row],[Jugador]]="jules",BD_ESTADISTICA_INF_B[[#This Row],[Jugador]]="JAN"),"PORTERO","JUGADOR") -> JUGADOR | T40: =IF(BD_ESTADISTICA_INF_B[[#This Row],[POSICION]]="jugador",BD_ESTADISTICA_INF_B[[#This Row],[Goles]],0) -> 1 | U40: =IF(BD_ESTADISTICA_INF_B[[#This Row],[POSICION]]="portero",BD_ESTADISTICA_INF_B[[#This Row],[Lanzam.]]-BD_ESTADISTICA_INF_B[[#This Row],[Paradas]],0) -> 0 | V40: =IF(BD_ESTADISTICA_INF_B[[#This Row],[POSICION]]="jugador",BD_ESTADISTICA_INF_B[[#This Row],[Lanzam.]],0) -> 2 | W40: =IF(BD_ESTADISTICA_INF_B[[#This Row],[POSICION]]="portero",BD_ESTADISTICA_INF_B[[#This Row],[Lanzam.]],0) -> 0
...

Sheet Analisis
N1: JORNADA | O1: (Todas)
D3: Suma de Goles | E3: Suma de Lanzam. | G3: Etiquetas de fila | H3: Suma de Campo1 | J3: Etiquetas de fila | K3: Suma de Goles | L3: Suma de Lanzam. | N3: Etiquetas de fila | R3: Asistencias | S3: Penaltis provocados | T3: Exclusiones provocadas | U3: Recuperaciones | X3: Pérdidas pase | Y3: Áreas | Z3: Perdidas otros | AA3: Exclusiones | AC3: Suma de Campo1
C4: 1 | D4: 1 | E4: 1 | G4: 1 | H4: 1 | J4: A. Espeso | K4: 5 | L4: 5 | N4: H.SANT QUIRZE(L) | Q4: 1 | R4: 8 | U4: 1 | W4: 1 | X4: 2 | AC4: 1 | AE4: Asistencias | AF4: Penaltis provocados | AG4: Exclusiones provocadas | AH4: Recuperaciones | AJ4: Suma de Exclusión | AK4: Suma de Pase | AL4: Suma de Área | AM4: Suma de Otro | AO4: 1 | AQ4: PROMEDIO RECUPERACIONES | AR4: =GETPIVOTDATA("Recuperaciones",$AE$4)/Analisis_Equipo!AI2 -> 0.28571429
C5: CH PALAUTORDERA (L) | D5: 1 | E5: 1 | G5: 3 | H5: 1 | J5: Total general | K5: 5 | L5: 5 | N5: VIROLAI (V) | Q5: CH PALAUTORDERA (L) | R5: 8 | U5: 1 | W5: CH PALAUTORDERA (L) | X5: 2 | AE5: 40 | AF5: 2 | AG5: 1 | AH5: 2 | AK5: 4 | AO5: 3 | AQ5: PROMEDIO EXC. PROVOCADAS | AR5: =GETPIVOTDATA("Exclusiones provocadas",$AE$4)/Analisis_Equipo!AI2 -> 0.14285714
C6: 3 | D6: 1 | E6: 1 | G6: 4 | H6: #DIV/0! | N6: CH PALAUTORDERA (L) | Q6: 3 | R6: 4 | W6: 3 | AO6: 4 | AQ6: PROMEDIO PENALTI PROVOCADOS | AR6: =GETPIVOTDATA("Penaltis provocados",$AE$4)/Analisis_Equipo!AI2 -> 0.28571429
C7: H.SANT QUIRZE(L) | D7: 1 | E7: 1 | G7: 5 | H7: 1 | N7: CH ESPLUGUES (V) | Q7: H.SANT QUIRZE(L) | R7: 4 | W7: H.SANT QUIRZE(L) | AO7: 5 | AQ7: PROMEDIO ASISTENCIAS | AR7: =GETPIVOTDATA("Asistencias",$AE$4)/Analisis_Equipo!AI2 -> 5.7142857
C8: 4 | G8: 6 | H8: #DIV/0! | N8: CREU ALTA SABADELL (L) | Q8: 4 | R8: 6 | S8: 1 | W8: 4 | X8: 1 | AO8: 6
C9: VIROLAI (V) | G9: 7 | H9: 1 | N9: UES SARRIA (L) | Q9: VIROLAI (V) | R9: 6 | S9: 1 | W9: VIROLAI (V) | X9: 1 | AO9: 7
C10: 5 | D10: 1 | E10: 1 | G10: Total general | H10: 1 | N10: Total general | Q10: 5 | R10: 6 | S10: 1 | T10: 1 | W10: 5 | AO10: Total general
C11: CREU ALTA SABADELL (L) | D11: 1 | E11: 1 | Q11: CREU ALTA SABADELL (L) | R11: 6 | S11: 1 | T11: 1 | W11: CREU ALTA SABADELL (L)
C12: 6 | Q12: 6 | R12: 8 | W12: 6
C13: CH ESPLUGUES (V) | Q13: CH ESPLUGUES (V) | R13: 8 | W13: CH ESPLUGUES (V)
C14: 7 | D14: 2 | E14: 2 | Q14: 7 | R14: 8 | U14: 1 | W14: 7 | X14: 1
C15: UES SARRIA (L) | D15: 2 | E15: 2 | Q15: UES SARRIA (L) | R15: 8 | U15: 1 | W15: UES SARRIA (L) | X15: 1
C16: Total general | D16: 5 | E16: 5 | Q16: Total general | R16: 40 | S16: 2 | T16: 1 | U16: 2 | W16: Total general | X16: 4

Sheet Analisis_Equipo
D2: Suma de goles favor | E2: Suma de lanzamientos realizados | F2: Suma de eficiencia | G2: Suma de goles favor | H2: Suma de lanzamientos realizados | I2: Suma de Campo11 | L2: Suma de Paradas | M2: Suma de goles contra | N2: Suma de eficiencia porteria | P2: Suma de goles contra | Q2: Suma de Paradas | R2: Suma de Campo12 | U2: Asistencias | V2: Penaltis provocados | W2: Exclusiones provocadas | X2: Recuperaciones | AA2: Pérdidas pase | AB2: Áreas | AC2: Perdidas otros | AD2: Exclusiones | AH2: NUMERO JORNADAS: | AI2: =MAX(Datos!O:O) -> 7 | AK2: Pérdidas pase | AL2: Áreas | AM2: Perdidas otros | AN2: Exclusiones
C3: 1 | D3: 39 | E3: 50 | F3: 78 | G3: 265 | H3: 314 | I3: 84.394904 | K3: 1 | L3: 9 | M3: 19 | N3: 32.142857 | P3: 97 | Q3: 56 | R3: 36.601307 | T3: 1 | U3: 24 | V3: 4 | W3: 3 | X3: 12 | Z3: 1 | AA3: 10 | AB3: 1 | AD3: 2 | AH3: GOLES A FAVOR | AI3: =GETPIVOTDATA("Suma de goles favor",$G$2) -> 265 | AK3: 35 | AL3: 2 | AM3: 1 | AN3: 16
C4: CH PALAUTORDERA (L) | D4: 39 | E4: 50 | F4: 78 | K4: CH PALAUTORDERA (L) | L4: 9 | M4: 19 | N4: 32.142857 | T4: CH PALAUTORDERA (L) | U4: 24 | V4: 4 | W4: 3 | X4: 12 | Z4: CH PALAUTORDERA (L) | AA4: 10 | AB4: 1 | AD4: 2 | AH4: GOLES EN CONTRA | AI4: =GETPIVOTDATA("Suma de goles contra",$P$2) -> 97 | AP4: Asistencias | AQ4: Penaltis provocados | AR4: Exclusiones provocadas | AS4: Recuperaciones | AU4: Pérdidas pase | AV4: Áreas | AW4: Perdidas otros | AX4: Exclusiones
C5: 3 | D5: 48 | E5: 54 | F5: 88.888889 | K5: 3 | L5: 6 | M5: 8 | N5: 42.857143 | T5: 3 | U5: 28 | V5: 1 | X5: 19 | Z5: 3 | AA5: 2 | AD5: 1 | AH5: PARADAS | AI5: =GETPIVOTDATA("Suma de Paradas",$P$2) -> 56 | AJ5: =AI5/AI2 -> 8 | AK5: Asistencias | AL5: Recuperaciones | AM5: Suma de Exclusión + | AP5: 153 | AQ5: 13 | AR5: 7 | AS5: 100 | AU5: 35 | AV5: 2 | AW5: 1 | AX5: 16
C6: H.SANT QUIRZE(L) | D6: 48 | E6: 54 | F6: 88.888889 | K6: H.SANT QUIRZE(L) | L6: 6 | M6: 8 | N6: 42.857143 | T6: H.SANT QUIRZE(L) | U6: 28 | V6: 1 | X6: 19 | Z6: H.SANT QUIRZE(L) | AA6: 2 | AD6: 1 | AH6: LANZ REALIZADOS | AI6: =GETPIVOTDATA("Suma de lanzamientos realizados",$G$2) -> 314 | AJ6: =AI6/AI2 -> 44.857143 | AK6: 153 | AL6: 100 | AM6: 7
C7: 4 | D7: 49 | E7: 55 | F7: 89.090909 | K7: 4 | L7: 11 | M7: 14 | N7: 44 | T7: 4 | U7: 25 | V7: 2 | W7: 2 | X7: 23 | Z7: 4 | AA7: 5 | AD7: 5 | AH7: EFICIENCIA | AI7: =GETPIVOTDATA("Suma de Campo11",$G$2) -> 84.394904
C8: VIROLAI (V) | D8: 49 | E8: 55 | F8: 89.090909 | K8: VIROLAI (V) | L8: 11 | M8: 14 | N8: 44 | T8: VIROLAI (V) | U8: 25 | V8: 2 | W8: 2 | X8: 23 | Z8: VIROLAI (V) | AA8: 5 | AD8: 5 | AH8: MEDIA METIDOS | AI8: =AI3/AI2 -> 37.857143
C9: 5 | D9: 50 | E9: 66 | F9: 75.757576 | K9: 5 | L9: 14 | M9: 24 | N9: 36.842105 | T9: 5 | U9: 25 | V9: 4 | W9: 2 | X9: 20 | Z9: 5 | AA9: 5 | AD9: 4 | AH9: PORCENTAJE PARADAS | AI9: =GETPIVOTDATA("Suma de Paradas",$P$2)/(AI4+AI5) -> 0.36601307
C10: CREU ALTA SABADELL (L) | D10: 50 | E10: 66 | F10: 75.757576 | K10: CREU ALTA SABADELL (L) | L10: 14 | M10: 24 | N10: 36.842105 | T10: CREU ALTA SABADELL (L) | U10: 25 | V10: 4 | W10: 2 | X10: 20 | Z10: CREU ALTA SABADELL (L) | AA10: 5 | AD10: 4 | AH10: MEDIA RECIBIDOS | AI10: =AI4/AI2 -> 13.857143
C11: 6 | D11: 37 | E11: 43 | F11: 86.046512 | K11: 6 | L11: 10 | M11: 17 | N11: 37.037037 | T11: 6 | U11: 27 | V11: 1 | X11: 12 | Z11: 6 | AA11: 6 | AB11: 1 | AD11: 2 | AH11: ASISTENCIAS | AI11: =GETPIVOTDATA("Asistencias",$AK$5) -> 153 | AJ11: =AI11/AI2 -> 21.857143
C12: CH ESPLUGUES (V) | D12: 37 | E12: 43 | F12: 86.046512 | K12: CH ESPLUGUES (V) | L12: 10 | M12: 17 | N12: 37.037037 | T12: CH ESPLUGUES (V) | U12: 27 | V12: 1 | X12: 12 | Z12: CH ESPLUGUES (V) | AA12: 6 | AB12: 1 | AD12: 2 | AH12: PERDIDAS | AI12: =GETPIVOTDATA("Pérdidas pase",$AK$2)+GETPIVOTDATA("Áreas",$AK$2)+GETPIVOTDATA("Perdidas otros",$AK$2) -> 38 | AJ12: =AI12/$AI$2 -> 5.4285714
C13: 7 | D13: 42 | E13: 46 | F13: 91.304348 | K13: 7 | L13: 6 | M13: 15 | N13: 28.571429 | T13: 7 | U13: 24 | V13: 1 | X13: 14 | Z13: 7 | AA13: 7 | AC13: 1 | AD13: 2 | AH13: RECUPERACIONES | AI13: =GETPIVOTDATA("Recuperaciones",$AK$5) -> 100 | AJ13: =AI13/$AI$2 -> 14.285714
C14: UES SARRIA (L) | D14: 42 | E14: 46 | F14: 91.304348 | K14: UES SARRIA (L) | L14: 6 | M14: 15 | N14: 28.571429 | T14: UES SARRIA (L) | U14: 24 | V14: 1 | X14: 14 | Z14: UES SARRIA (L) | AA14: 7 | AC14: 1 | AD14: 2 | AH14: EXCLUSION + | AI14: =GETPIVOTDATA("Suma de Exclusión +",$AK$5) -> 7 | AJ14: =AI14/$AI$2 -> 1
C15: Total general | D15: 265 | E15: 314 | F15: 84.394904 | K15: Total general | L15: 56 | M15: 97 | N15: 36.601307 | T15: Total general | U15: 153 | V15: 13 | W15: 7 | X15: 100 | Z15: Total general | AA15: 35 | AB15: 2 | AC15: 1 | AD15: 16 | AH15: EXCLUSION - | AI15: =GETPIVOTDATA("Exclusiones",$AK$2) -> 16 | AJ15: =AI15/$AI$2 -> 2.2857143
AH16: PENALTIS PROVOCADOS | AI16: =GETPIVOTDATA("Penaltis provocados",$T$2) -> 13
AH17: PERDIDAS PASE | AI17: =GETPIVOTDATA("Pérdidas pase",$Z$2) -> 35
AH18: PERDIDAS OTROS | AI18: =GETPIVOTDATA("Perdidas otros",$Z$2) -> 1
AH19: AREA | AI19: =GETPIVOTDATA("Áreas",$Z$2) -> 2

Sheet Individual

Sheet Equipo

Sheet fitlro_individual
A2: SELECCIONAR TIPO GRÁFICO: | D2: Goles/Lanzamientos
D7: acciones negativas

Sheet filtro_equipo
A2: SELECCIONAR TIPO GRÁFICO: | D2: Goles/Lanzamientos/Eficiencia
D7: acciones negativas

Sheet cuadro desplegable
C4: Goles/Lanzamientos | D4: Eficiencia | E4: Acciones positivas | F4: Acciones negativas | G4: "SELECCIONAR TIPO GRÁFICO"
C8: Goles/Lanzamientos/Eficiencia | D8: Acciones Positivas | E8: Acciones Negativas

Sheet J1_Individual
